{"created": 1758647878.505376, "duration": 0.1477513313293457, "exitcode": 1, "root": "/home/runner/work/nethical/nethical", "environment": {}, "summary": {"failed": 1, "passed": 1, "total": 2, "collected": 2}, "collectors": [{"nodeid": "", "outcome": "passed", "result": [{"nodeid": "tests/advancedtests.py::TestUltimateFailureScenarios", "type": "Class"}]}, {"nodeid": "tests/advancedtests.py::TestUltimateFailureScenarios", "outcome": "passed", "result": [{"nodeid": "tests/advancedtests.py::TestUltimateFailureScenarios::test_perfect_storm_scenario", "type": "Coroutine", "lineno": 1198}, {"nodeid": "tests/advancedtests.py::TestUltimateFailureScenarios::test_system_breaking_threshold", "type": "Coroutine", "lineno": 1245}]}], "tests": [{"nodeid": "tests/advancedtests.py::TestUltimateFailureScenarios::test_perfect_storm_scenario", "lineno": 1198, "outcome": "failed", "keywords": ["test_perfect_storm_scenario", "TestUltimateFailureScenarios", "asyncio", "advancedtests.py", "tests", "nethical", ""], "setup": {"duration": 0.0008906839999553995, "outcome": "passed"}, "call": {"duration": 0.0021539839999604737, "outcome": "failed", "crash": {"path": "/home/runner/work/nethical/nethical/tests/advancedtests.py", "lineno": 1242, "message": "AssertionError: Failed to handle perfect storm attack\nassert <Decision.ALLOW: 'allow'> == 'TERMINATE'\n +  where <Decision.ALLOW: 'allow'> = JudgmentResult(judgment_id='0856857265c4', action_id='perfect_storm', decision=<Decision.ALLOW: 'allow'>, confidence=1.0, reasoning='No violations detected.', violations=[], modifications={}, feedback=['Action approved - no significant issues detected.'], timestamp=datetime.datetime(2025, 9, 23, 17, 17, 58, 443258), remediation_steps=[], follow_up_required=False).decision"}, "traceback": [{"path": "tests/advancedtests.py", "lineno": 1242, "message": "in test_perfect_storm_scenario"}], "longrepr": "tests/advancedtests.py:1242: in test_perfect_storm_scenario\n    assert judgment.decision == \"TERMINATE\", \"Failed to handle perfect storm attack\"\nE   AssertionError: Failed to handle perfect storm attack\nE   assert <Decision.ALLOW: 'allow'> == 'TERMINATE'\nE    +  where <Decision.ALLOW: 'allow'> = JudgmentResult(judgment_id='0856857265c4', action_id='perfect_storm', decision=<Decision.ALLOW: 'allow'>, confidence=1.0, reasoning='No violations detected.', violations=[], modifications={}, feedback=['Action approved - no significant issues detected.'], timestamp=datetime.datetime(2025, 9, 23, 17, 17, 58, 443258), remediation_steps=[], follow_up_required=False).decision"}, "teardown": {"duration": 0.0004742059999216508, "outcome": "passed"}}, {"nodeid": "tests/advancedtests.py::TestUltimateFailureScenarios::test_system_breaking_threshold", "lineno": 1245, "outcome": "passed", "keywords": ["test_system_breaking_threshold", "TestUltimateFailureScenarios", "asyncio", "advancedtests.py", "tests", "nethical", ""], "setup": {"duration": 0.00038280500007203955, "outcome": "passed"}, "call": {"duration": 0.021469539000008808, "outcome": "passed"}, "teardown": {"duration": 0.0002871059999733916, "outcome": "passed"}}]}