{"created": 1758647874.4730976, "duration": 0.1355915069580078, "exitcode": 1, "root": "/home/runner/work/nethical/nethical", "environment": {}, "summary": {"failed": 1, "passed": 1, "total": 2, "collected": 2}, "collectors": [{"nodeid": "", "outcome": "passed", "result": [{"nodeid": "tests/advancedtests.py::TestRecoveryAndFailsafes", "type": "Class"}]}, {"nodeid": "tests/advancedtests.py::TestRecoveryAndFailsafes", "outcome": "passed", "result": [{"nodeid": "tests/advancedtests.py::TestRecoveryAndFailsafes::test_component_failure_recovery", "type": "Coroutine", "lineno": 652}, {"nodeid": "tests/advancedtests.py::TestRecoveryAndFailsafes::test_cascading_failure_prevention", "type": "Coroutine", "lineno": 674}]}], "tests": [{"nodeid": "tests/advancedtests.py::TestRecoveryAndFailsafes::test_component_failure_recovery", "lineno": 652, "outcome": "failed", "keywords": ["test_component_failure_recovery", "TestRecoveryAndFailsafes", "asyncio", "advancedtests.py", "tests", "nethical", ""], "setup": {"duration": 0.0008856839999680233, "outcome": "passed"}, "call": {"duration": 0.0019663219999301873, "outcome": "failed", "crash": {"path": "/home/runner/work/nethical/nethical/tests/advancedtests.py", "lineno": 673, "message": "assert <Decision.BLOCK: 'block'> in ['RESTRICT', 'BLOCK', 'TERMINATE']\n +  where <Decision.BLOCK: 'block'> = JudgmentResult(judgment_id='6ab1557b3772', action_id='failure_test', decision=<Decision.BLOCK: 'block'>, confidence=0.0, reasoning=\"Error during evaluation: object MagicMock can't be used in 'await' expression\", violations=[], modifications={}, feedback=['System error - action blocked for safety'], timestamp=datetime.datetime(2025, 9, 23, 17, 17, 54, 421661), remediation_steps=[], follow_up_required=False).decision"}, "traceback": [{"path": "tests/advancedtests.py", "lineno": 673, "message": "in test_component_failure_recovery"}], "log": [{"name": "nethical.core.governance", "msg": "Error evaluating action failure_test: object MagicMock can't be used in 'await' expression", "args": null, "levelname": "ERROR", "levelno": 40, "pathname": "/home/runner/work/nethical/nethical/nethical/core/governance.py", "filename": "governance.py", "module": "governance", "exc_info": null, "exc_text": null, "stack_info": null, "lineno": 996, "funcName": "evaluate_action", "created": 1758647874.4215584, "msecs": 421.0, "relativeCreated": 152.73308753967285, "thread": 140014347423872, "threadName": "MainThread", "processName": "MainProcess", "process": 3708, "taskName": "Task-1"}], "longrepr": "tests/advancedtests.py:673: in test_component_failure_recovery\n    assert judgment.decision in [\"RESTRICT\", \"BLOCK\", \"TERMINATE\"]\nE   assert <Decision.BLOCK: 'block'> in ['RESTRICT', 'BLOCK', 'TERMINATE']\nE    +  where <Decision.BLOCK: 'block'> = JudgmentResult(judgment_id='6ab1557b3772', action_id='failure_test', decision=<Decision.BLOCK: 'block'>, confidence=0.0, reasoning=\"Error during evaluation: object MagicMock can't be used in 'await' expression\", violations=[], modifications={}, feedback=['System error - action blocked for safety'], timestamp=datetime.datetime(2025, 9, 23, 17, 17, 54, 421661), remediation_steps=[], follow_up_required=False).decision"}, "teardown": {"duration": 0.0004608210000469626, "outcome": "passed"}}, {"nodeid": "tests/advancedtests.py::TestRecoveryAndFailsafes::test_cascading_failure_prevention", "lineno": 674, "outcome": "passed", "keywords": ["test_cascading_failure_prevention", "TestRecoveryAndFailsafes", "asyncio", "advancedtests.py", "tests", "nethical", ""], "setup": {"duration": 0.0004114280000067083, "outcome": "passed"}, "call": {"duration": 0.01224598299995705, "outcome": "passed"}, "teardown": {"duration": 0.00027659700003823673, "outcome": "passed"}}]}