Test Class: TestUltimateFailureScenarios
Timestamp: 2025-09-23T17:17:58.562441
============================================================
STDOUT:
============================= test session starts ==============================
platform linux -- Python 3.12.3, pytest-8.4.2, pluggy-1.6.0 -- /usr/bin/python
cachedir: .pytest_cache
metadata: {'Python': '3.12.3', 'Platform': 'Linux-6.11.0-1018-azure-x86_64-with-glibc2.39', 'Packages': {'pytest': '8.4.2', 'pluggy': '1.6.0'}, 'Plugins': {'json-report': '1.5.0', 'metadata': '3.1.1', 'asyncio': '1.2.0'}, 'CI': 'true', 'JAVA_HOME': '/usr/lib/jvm/temurin-17-jdk-amd64'}
rootdir: /home/runner/work/nethical/nethical
configfile: pyproject.toml
plugins: json-report-1.5.0, metadata-3.1.1, asyncio-1.2.0
asyncio: mode=Mode.AUTO, debug=False, asyncio_default_fixture_loop_scope=None, asyncio_default_test_loop_scope=function
collecting ... collected 2 items

tests/advancedtests.py::TestUltimateFailureScenarios::test_perfect_storm_scenario FAILED [ 50%]
tests/advancedtests.py::TestUltimateFailureScenarios::test_system_breaking_threshold PASSED [100%]

=================================== FAILURES ===================================
___________ TestUltimateFailureScenarios.test_perfect_storm_scenario ___________
tests/advancedtests.py:1242: in test_perfect_storm_scenario
    assert judgment.decision == "TERMINATE", "Failed to handle perfect storm attack"
E   AssertionError: Failed to handle perfect storm attack
E   assert <Decision.ALLOW: 'allow'> == 'TERMINATE'
E    +  where <Decision.ALLOW: 'allow'> = JudgmentResult(judgment_id='0856857265c4', action_id='perfect_storm', decision=<Decision.ALLOW: 'allow'>, confidence=1.0, reasoning='No violations detected.', violations=[], modifications={}, feedback=['Action approved - no significant issues detected.'], timestamp=datetime.datetime(2025, 9, 23, 17, 17, 58, 443258), remediation_steps=[], follow_up_required=False).decision
--------------------------------- JSON report ----------------------------------
report saved to: tests/results/individual/testultimatefailurescenarios_results.json
=========================== short test summary info ============================
FAILED tests/advancedtests.py::TestUltimateFailureScenarios::test_perfect_storm_scenario - AssertionError: Failed to handle perfect storm attack
assert <Decision.ALLOW: 'allow'> == 'TERMINATE'
 +  where <Decision.ALLOW: 'allow'> = JudgmentResult(judgment_id='0856857265c4', action_id='perfect_storm', decision=<Decision.ALLOW: 'allow'>, confidence=1.0, reasoning='No violations detected.', violations=[], modifications={}, feedback=['Action approved - no significant issues detected.'], timestamp=datetime.datetime(2025, 9, 23, 17, 17, 58, 443258), remediation_steps=[], follow_up_required=False).decision
========================= 1 failed, 1 passed in 0.15s ==========================

============================================================
STDERR:

